<sdf version='1.11'>
  <model name='ur'>
    <joint name='base_joint' type='fixed'>
      <pose relative_to='__model__'>0 0 0 0 0 0</pose>
      <parent>world</parent>
      <child>base_link</child>
    </joint>
    <link name='base_link'>
      <pose relative_to='base_joint'>0 0 0 0 0 0</pose>
      <inertial>
        <pose>0 0 0 0 0 0</pose>
        <mass>4</mass>
        <inertia>
          <ixx>0.0044333315599999999</ixx>
          <ixy>0</ixy>
          <ixz>0</ixz>
          <iyy>0.0044333315599999999</iyy>
          <iyz>0</iyz>
          <izz>0.0071999999999999998</izz>
        </inertia>
      </inertial>
      <collision name='base_link_inertia_collision'>
        <pose>0 0 0 0 0 -2.4492935982947059e-16</pose>
        <geometry>
          <mesh>
            <scale>1 1 1</scale>
            <uri>model://ur_description/meshes/ur5/collision/base.stl</uri>
          </mesh>
        </geometry>
      </collision>
      <visual name='base_link_inertia_visual'>
        <pose>0 0 0 0 0 -2.4492935982947059e-16</pose>
        <geometry>
          <mesh>
            <scale>1 1 1</scale>
            <uri>model://ur_description/meshes/ur5/visual/base.dae</uri>
          </mesh>
        </geometry>
      </visual>
    </link>
    <joint name='shoulder_pan_joint' type='revolute'>
      <pose relative_to='base_link'>0 0 0.089159000000000002 0 0 3.1415926535897931</pose>
      <parent>base_link</parent>
      <child>shoulder_link</child>
      <axis>
        <xyz>0 0 1</xyz>
        <limit>
          <lower>-6.2831853071795862</lower>
          <upper>6.2831853071795862</upper>
          <effort>150</effort>
          <velocity>3.1415926535897931</velocity>
        </limit>
        <dynamics>
          <damping>0</damping>
          <friction>0</friction>
          <spring_reference>0</spring_reference>
          <spring_stiffness>0</spring_stiffness>
        </dynamics>
      </axis>
    </joint>
    <link name='shoulder_link'>
      <pose relative_to='shoulder_pan_joint'>0 0 0 0 0 0</pose>
      <inertial>
        <pose>0 -0.0019300000000000001 -0.025610000000000001 0 0 0</pose>
        <mass>3.7000000000000002</mass>
        <inertia>
          <ixx>0.01497235833333333</ixx>
          <ixy>0</ixy>
          <ixz>0</ixz>
          <iyy>0.01497235833333333</iyy>
          <iyz>0</iyz>
          <izz>0.010406250000000001</izz>
        </inertia>
      </inertial>
      <collision name='shoulder_link_collision'>
        <pose>0 0 0 0 0 3.1415926535897931</pose>
        <geometry>
          <mesh>
            <scale>1 1 1</scale>
            <uri>model://ur_description/meshes/ur5/collision/shoulder.stl</uri>
          </mesh>
        </geometry>
      </collision>
      <visual name='shoulder_link_visual'>
        <pose>0 0 0 0 0 3.1415926535897931</pose>
        <geometry>
          <mesh>
            <scale>1 1 1</scale>
            <uri>model://ur_description/meshes/ur5/visual/shoulder.dae</uri>
          </mesh>
        </geometry>
      </visual>
    </link>
    <joint name='shoulder_lift_joint' type='revolute'>
      <pose relative_to='shoulder_link'>0 0 0 1.5707963270000003 0 0</pose>
      <parent>shoulder_link</parent>
      <child>upper_arm_link</child>
      <axis>
        <xyz>0 0 1</xyz>
        <limit>
          <lower>-6.2831853071795862</lower>
          <upper>6.2831853071795862</upper>
          <effort>150</effort>
          <velocity>3.1415926535897931</velocity>
        </limit>
        <dynamics>
          <damping>0</damping>
          <friction>0</friction>
          <spring_reference>0</spring_reference>
          <spring_stiffness>0</spring_stiffness>
        </dynamics>
      </axis>
    </joint>
    <link name='upper_arm_link'>
      <pose relative_to='shoulder_lift_joint'>0 0 0 0 0 0</pose>
      <inertial>
        <pose>-0.21249999999999999 0 0.11336 0 1.5707963267948966 0</pose>
        <mass>8.3930000000000007</mass>
        <inertia>
          <ixx>0.13388583541666671</ixx>
          <ixy>0</ixy>
          <ixz>0</ixz>
          <iyy>0.13388583541666671</iyy>
          <iyz>0</iyz>
          <izz>0.0151074</izz>
        </inertia>
      </inertial>
      <collision name='upper_arm_link_collision'>
        <pose>0 0 0.13585 1.5707963267948959 5.5511151231257827e-17 -1.5707963267948959</pose>
        <geometry>
          <mesh>
            <scale>1 1 1</scale>
            <uri>model://ur_description/meshes/ur5/collision/upperarm.stl</uri>
          </mesh>
        </geometry>
      </collision>
      <visual name='upper_arm_link_visual'>
        <pose>0 0 0.13585 1.5707963267948959 5.5511151231257827e-17 -1.5707963267948959</pose>
        <geometry>
          <mesh>
            <scale>1 1 1</scale>
            <uri>model://ur_description/meshes/ur5/visual/upperarm.dae</uri>
          </mesh>
        </geometry>
      </visual>
    </link>
    <joint name='elbow_joint' type='revolute'>
      <pose relative_to='upper_arm_link'>-0.42499999999999999 0 0 0 0 0</pose>
      <parent>upper_arm_link</parent>
      <child>forearm_link</child>
      <axis>
        <xyz>0 0 1</xyz>
        <limit>
          <lower>-3.1415926535897931</lower>
          <upper>3.1415926535897931</upper>
          <effort>150</effort>
          <velocity>3.1415926535897931</velocity>
        </limit>
        <dynamics>
          <damping>0</damping>
          <friction>0</friction>
          <spring_reference>0</spring_reference>
          <spring_stiffness>0</spring_stiffness>
        </dynamics>
      </axis>
    </joint>
    <link name='forearm_link'>
      <pose relative_to='elbow_joint'>0 0 0 0 0 0</pose>
      <inertial>
        <pose>-0.24224999999999999 0 0.026499999999999999 0 1.5707963267948966 0</pose>
        <mass>2.3300000000000001</mass>
        <inertia>
          <ixx>0.031216803515624999</ixx>
          <ixy>0</ixy>
          <ixz>0</ixz>
          <iyy>0.031216803515624999</iyy>
          <iyz>0</iyz>
          <izz>0.0040949999999999997</izz>
        </inertia>
      </inertial>
      <collision name='forearm_link_collision'>
        <pose>0 0 0.016500000000000001 1.5707963267948959 5.5511151231257827e-17 -1.5707963267948959</pose>
        <geometry>
          <mesh>
            <scale>1 1 1</scale>
            <uri>model://ur_description/meshes/ur5/collision/forearm.stl</uri>
          </mesh>
        </geometry>
      </collision>
      <visual name='forearm_link_visual'>
        <pose>0 0 0.016500000000000001 1.5707963267948959 5.5511151231257827e-17 -1.5707963267948959</pose>
        <geometry>
          <mesh>
            <scale>1 1 1</scale>
            <uri>model://ur_description/meshes/ur5/visual/forearm.dae</uri>
          </mesh>
        </geometry>
      </visual>
    </link>
    <joint name='wrist_1_joint' type='revolute'>
      <pose relative_to='forearm_link'>-0.39224999999999999 0 0.10915 0 0 0</pose>
      <parent>forearm_link</parent>
      <child>wrist_1_link</child>
      <axis>
        <xyz>0 0 1</xyz>
        <limit>
          <lower>-6.2831853071795862</lower>
          <upper>6.2831853071795862</upper>
          <effort>28</effort>
          <velocity>3.1415926535897931</velocity>
        </limit>
        <dynamics>
          <damping>0</damping>
          <friction>0</friction>
          <spring_reference>0</spring_reference>
          <spring_stiffness>0</spring_stiffness>
        </dynamics>
      </axis>
    </joint>
    <link name='wrist_1_link'>
      <pose relative_to='wrist_1_joint'>0 0 0 0 0 0</pose>
      <inertial>
        <pose>0 -0.01634 -0.0018 0 0 0</pose>
        <mass>1.2190000000000001</mass>
        <inertia>
          <ixx>0.0020138895833333331</ixx>
          <ixy>0</ixy>
          <ixz>0</ixz>
          <iyy>0.0020138895833333331</iyy>
          <iyz>0</iyz>
          <izz>0.0021941999999999999</izz>
        </inertia>
      </inertial>
      <collision name='wrist_1_link_collision'>
        <pose>0 0 -0.092999999999999999 1.5707963267948959 0 0</pose>
        <geometry>
          <mesh>
            <scale>1 1 1</scale>
            <uri>model://ur_description/meshes/ur5/collision/wrist1.stl</uri>
          </mesh>
        </geometry>
      </collision>
      <visual name='wrist_1_link_visual'>
        <pose>0 0 -0.092999999999999999 1.5707963267948959 0 0</pose>
        <geometry>
          <mesh>
            <scale>1 1 1</scale>
            <uri>model://ur_description/meshes/ur5/visual/wrist1.dae</uri>
          </mesh>
        </geometry>
      </visual>
    </link>
    <joint name='wrist_2_joint' type='revolute'>
      <pose relative_to='wrist_1_link'>0 -0.094649999999999998 -1.941303950897609e-11 1.5707963270000003 0 0</pose>
      <parent>wrist_1_link</parent>
      <child>wrist_2_link</child>
      <axis>
        <xyz>0 0 1</xyz>
        <limit>
          <lower>-6.2831853071795862</lower>
          <upper>6.2831853071795862</upper>
          <effort>28</effort>
          <velocity>3.1415926535897931</velocity>
        </limit>
        <dynamics>
          <damping>0</damping>
          <friction>0</friction>
          <spring_reference>0</spring_reference>
          <spring_stiffness>0</spring_stiffness>
        </dynamics>
      </axis>
    </joint>
    <link name='wrist_2_link'>
      <pose relative_to='wrist_2_joint'>0 0 0 0 0 0</pose>
      <inertial>
        <pose>0 0.01634 -0.0018 0 0 0</pose>
        <mass>1.2190000000000001</mass>
        <inertia>
          <ixx>0.001831039583333333</ixx>
          <ixy>0</ixy>
          <ixz>0</ixz>
          <iyy>0.001831039583333333</iyy>
          <iyz>0</iyz>
          <izz>0.0021941999999999999</izz>
        </inertia>
      </inertial>
      <collision name='wrist_2_link_collision'>
        <pose>0 0 -0.095000000000000001 0 0 0</pose>
        <geometry>
          <mesh>
            <scale>1 1 1</scale>
            <uri>model://ur_description/meshes/ur5/collision/wrist2.stl</uri>
          </mesh>
        </geometry>
      </collision>
      <visual name='wrist_2_link_visual'>
        <pose>0 0 -0.095000000000000001 0 0 0</pose>
        <geometry>
          <mesh>
            <scale>1 1 1</scale>
            <uri>model://ur_description/meshes/ur5/visual/wrist2.dae</uri>
          </mesh>
        </geometry>
      </visual>
    </link>
    <joint name='wrist_3_joint' type='revolute'>
      <pose relative_to='wrist_2_link'>0 0.082299999999999998 -1.6880012166811751e-11 -1.5707963270000003 1.2246467991473527e-16 -1.224646799147353e-16</pose>
      <parent>wrist_2_link</parent>
      <child>wrist_3_link</child>
      <axis>
        <xyz>0 0 1</xyz>
        <limit>
          <lower>-6.2831853071795862</lower>
          <upper>6.2831853071795862</upper>
          <effort>28</effort>
          <velocity>3.1415926535897931</velocity>
        </limit>
        <dynamics>
          <damping>0</damping>
          <friction>0</friction>
          <spring_reference>0</spring_reference>
          <spring_stiffness>0</spring_stiffness>
        </dynamics>
      </axis>
    </joint>
    <link name='wrist_3_link'>
      <pose relative_to='wrist_3_joint'>0 0 0 0 0 0</pose>
      <inertial>
        <pose>0 0 -0.0011590000000000001 0 0 0</pose>
        <mass>0.18790000000000001</mass>
        <inertia>
          <ixx>8.0624758333333322e-05</ixx>
          <ixy>0</ixy>
          <ixz>0</ixz>
          <iyy>8.0624758333333322e-05</iyy>
          <iyz>0</iyz>
          <izz>0.00013211718749999999</izz>
        </inertia>
      </inertial>
      <collision name='wrist_3_link_collision'>
        <pose>0 0 -0.081799999999999998 1.5707963267948959 0 0</pose>
        <geometry>
          <mesh>
            <scale>1 1 1</scale>
            <uri>model://ur_description/meshes/ur5/collision/wrist3.stl</uri>
          </mesh>
        </geometry>
      </collision>
      <visual name='wrist_3_link_visual'>
        <pose>0 0 -0.081799999999999998 1.5707963267948959 0 0</pose>
        <geometry>
          <mesh>
            <scale>1 1 1</scale>
            <uri>model://ur_description/meshes/ur5/visual/wrist3.dae</uri>
          </mesh>
        </geometry>
      </visual>
    </link>
    <frame name='base_link-base_fixed_joint' attached_to='base_link'>
      <pose>0 0 0 0 0 3.1415926535897931</pose>
    </frame>
    <frame name='base' attached_to='base_link-base_fixed_joint'>
      <pose>0 0 0 0 0 0</pose>
    </frame>
    <frame name='base_link-base_link_inertia' attached_to='base_link'>
      <pose>0 0 0 0 0 3.1415926535897931</pose>
    </frame>
    <frame name='base_link_inertia' attached_to='base_link-base_link_inertia'>
      <pose>0 0 0 0 0 0</pose>
    </frame>
    <frame name='flange-tool0' attached_to='flange'>
      <pose>0 0 0 1.5707963267948959 -5.5511151231257827e-17 1.5707963267948959</pose>
    </frame>
    <frame name='tool0' attached_to='flange-tool0'>
      <pose>0 0 0 0 0 0</pose>
    </frame>
    <frame name='wrist_3-flange' attached_to='wrist_3_link'>
      <pose>0 0 0 -1.5707963267948957 -1.5707963267948966 0</pose>
    </frame>
    <frame name='flange' attached_to='wrist_3-flange'>
      <pose>0 0 0 0 0 0</pose>
    </frame>
    <frame name='wrist_3_link-ft_frame' attached_to='wrist_3_link'>
      <pose>0 0 0 3.1415926535897931 0 0</pose>
    </frame>
    <frame name='ft_frame' attached_to='wrist_3_link-ft_frame'>
      <pose>0 0 0 0 0 0</pose>
    </frame>
  </model>
</sdf>
